=== EXAM OS SIMULATION LOG ===

[ 1659914 ms] [INFO ] [SCHEDULER ] Scheduler initialized
[ 1659915 ms] [INFO ] [MEMORY    ] Memory subsystem initialized
[ 1659915 ms] [INFO ] [IO        ] I/O buffer initialized
[ 1659915 ms] [INFO ] [INTERRUPT ] Interrupt vector table initialized (4 handlers)
[ 1659915 ms] [INFO ] [SCHEDULER ] Scheduler thread started
[ 1659915 ms] [INFO ] [MEMORY    ] Memory thread started
[ 1659915 ms] [INFO ] [IO        ] I/O buffer thread started
[ 1659915 ms] [INFO ] [INTERRUPT ] Interrupt handler thread started
[ 1660816 ms] [INFO ] [SCHEDULER ] PID 1 added to ready queue (remaining=92 ticks)
[ 1660816 ms] [INFO ] [SCHEDULER ] PID 2 added to ready queue (remaining=100 ticks)
[ 1660816 ms] [INFO ] [SCHEDULER ] PID 3 added to ready queue (remaining=98 ticks)
[ 1660816 ms] [INFO ] [SCHEDULER ] PID 4 added to ready queue (remaining=95 ticks)
[ 1660816 ms] [INFO ] [SCHEDULER ] PID 5 added to ready queue (remaining=100 ticks)
[ 1660816 ms] [WARN ] [MEMORY    ] Page fault: PID 0 page 1
[ 1660817 ms] [WARN ] [MEMORY    ] Page fault: PID 0 page 4
[ 1660817 ms] [WARN ] [MEMORY    ] Page fault: PID 0 page 0
[ 1660918 ms] [WARN ] [MEMORY    ] Page fault: PID 0 page 3
[ 1661016 ms] [INFO ] [IO        ] PID 1 submitted Q8
[ 1661119 ms] [WARN ] [MEMORY    ] Page fault: PID 0 page 6
[ 1661317 ms] [INFO ] [IO        ] PID 1 submitted Q2
[ 1661319 ms] [WARN ] [MEMORY    ] Page fault: PID 0 page 5
[ 1661417 ms] [INFO ] [IO        ] Flushed 2 submissions to disk
[ 1661420 ms] [WARN ] [MEMORY    ] Page fault: PID 0 page 2
[ 1661517 ms] [INFO ] [IO        ] PID 1 submitted Q1
[ 1661721 ms] [WARN ] [MEMORY    ] Page fault: PID 0 page 7
[ 1661867 ms] [INFO ] [SCHEDULER ] PID 6 added to ready queue (remaining=98 ticks)
[ 1661867 ms] [INFO ] [SCHEDULER ] PID 7 added to ready queue (remaining=100 ticks)
[ 1661867 ms] [INFO ] [SCHEDULER ] PID 8 added to ready queue (remaining=94 ticks)
[ 1661867 ms] [INFO ] [SCHEDULER ] PID 9 added to ready queue (remaining=93 ticks)
[ 1661867 ms] [INFO ] [SCHEDULER ] PID 10 added to ready queue (remaining=100 ticks)
[ 1661917 ms] [INFO ] [IO        ] PID 1 submitted Q2
[ 1662317 ms] [INFO ] [IO        ] PID 1 submitted Q9
[ 1662518 ms] [INFO ] [IO        ] PID 1 submitted Q5
[ 1662818 ms] [WARN ] [IO        ] SUBMISSION STORM triggered — 30 simultaneous submissions!
[ 1662818 ms] [INFO ] [IO        ] PID 1 submitted Q2
[ 1662818 ms] [INFO ] [IO        ] PID 2 submitted Q4
[ 1662818 ms] [INFO ] [IO        ] PID 3 submitted Q1
[ 1662818 ms] [INFO ] [IO        ] PID 4 submitted Q10
[ 1662818 ms] [INFO ] [IO        ] PID 5 submitted Q1
[ 1662818 ms] [INFO ] [IO        ] PID 6 submitted Q2
[ 1662818 ms] [INFO ] [IO        ] PID 7 submitted Q1
[ 1662818 ms] [INFO ] [IO        ] PID 8 submitted Q6
[ 1662818 ms] [INFO ] [IO        ] PID 9 submitted Q5
[ 1662818 ms] [INFO ] [IO        ] PID 10 submitted Q6
[ 1662818 ms] [INFO ] [IO        ] Flushed 14 submissions to disk
[ 1663118 ms] [INFO ] [IO        ] PID 1 submitted Q10
[ 1663569 ms] [INFO ] [SCHEDULER ] PID 1 terminated
[ 1663569 ms] [INFO ] [SCHEDULER ] PID 1 completed exam (PRIORITY)
[ 1663719 ms] [INFO ] [IO        ] PID 9 submitted Q5
[ 1663723 ms] [WARN ] [MEMORY    ] Page fault: PID 8 page 0
[ 1663724 ms] [WARN ] [MEMORY    ] Page fault: PID 8 page 5
[ 1663820 ms] [INFO ] [SCHEDULER ] PID 11 added to ready queue (remaining=92 ticks)
[ 1663820 ms] [INFO ] [SCHEDULER ] PID 12 added to ready queue (remaining=99 ticks)
[ 1663820 ms] [INFO ] [SCHEDULER ] PID 13 added to ready queue (remaining=100 ticks)
[ 1663820 ms] [INFO ] [SCHEDULER ] PID 14 added to ready queue (remaining=97 ticks)
[ 1663820 ms] [INFO ] [SCHEDULER ] PID 15 added to ready queue (remaining=91 ticks)
[ 1663824 ms] [WARN ] [MEMORY    ] Page fault: PID 8 page 3
[ 1663825 ms] [WARN ] [MEMORY    ] Page fault: PID 8 page 4
[ 1663926 ms] [WARN ] [MEMORY    ] Page fault: PID 8 page 1
[ 1663926 ms] [WARN ] [MEMORY    ] Page fault: PID 8 page 7
[ 1664027 ms] [WARN ] [MEMORY    ] Page fault: PID 8 page 2
[ 1664119 ms] [INFO ] [IO        ] PID 9 submitted Q9
[ 1664320 ms] [INFO ] [IO        ] Flushed 3 submissions to disk
[ 1664428 ms] [WARN ] [MEMORY    ] Page fault: PID 8 page 6
[ 1664620 ms] [INFO ] [IO        ] PID 9 submitted Q5
[ 1664872 ms] [INFO ] [SCHEDULER ] PID 16 added to ready queue (remaining=94 ticks)
[ 1664872 ms] [INFO ] [SCHEDULER ] PID 17 added to ready queue (remaining=96 ticks)
[ 1664872 ms] [INFO ] [SCHEDULER ] PID 18 added to ready queue (remaining=92 ticks)
[ 1664872 ms] [INFO ] [SCHEDULER ] PID 19 added to ready queue (remaining=94 ticks)
[ 1664872 ms] [INFO ] [SCHEDULER ] PID 20 added to ready queue (remaining=100 ticks)
[ 1664920 ms] [INFO ] [IO        ] PID 9 submitted Q9
[ 1665220 ms] [INFO ] [IO        ] PID 9 submitted Q4
[ 1665320 ms] [INFO ] [IO        ] PID 9 submitted Q1
[ 1665421 ms] [INFO ] [IO        ] PID 9 submitted Q4
[ 1665821 ms] [INFO ] [IO        ] Flushed 5 submissions to disk
[ 1666021 ms] [INFO ] [IO        ] PID 9 submitted Q10
[ 1666424 ms] [INFO ] [SCHEDULER ] PID 9 terminated
[ 1666424 ms] [INFO ] [SCHEDULER ] PID 9 completed exam (PRIORITY)
[ 1666522 ms] [INFO ] [IO        ] PID 9 submitted Q9
[ 1666530 ms] [WARN ] [MEMORY    ] Page fault: PID 14 page 0
[ 1666531 ms] [WARN ] [MEMORY    ] Page fault: PID 14 page 7
[ 1666632 ms] [WARN ] [MEMORY    ] Page fault: PID 14 page 6
[ 1666632 ms] [WARN ] [MEMORY    ] Page fault: PID 14 page 2
[ 1666733 ms] [WARN ] [MEMORY    ] Page fault: PID 14 page 1
[ 1666734 ms] [WARN ] [MEMORY    ] Page fault: PID 14 page 3
[ 1666825 ms] [INFO ] [SCHEDULER ] PID 21 added to ready queue (remaining=96 ticks)
[ 1666825 ms] [INFO ] [SCHEDULER ] PID 22 added to ready queue (remaining=100 ticks)
[ 1666825 ms] [INFO ] [SCHEDULER ] PID 23 added to ready queue (remaining=100 ticks)
[ 1666825 ms] [INFO ] [SCHEDULER ] PID 24 added to ready queue (remaining=94 ticks)
[ 1666825 ms] [INFO ] [SCHEDULER ] PID 25 added to ready queue (remaining=98 ticks)
[ 1666834 ms] [WARN ] [MEMORY    ] Page fault: PID 14 page 4
[ 1666922 ms] [INFO ] [IO        ] PID 15 submitted Q8
[ 1667222 ms] [INFO ] [IO        ] PID 15 submitted Q8
[ 1667322 ms] [INFO ] [IO        ] Flushed 4 submissions to disk
[ 1667535 ms] [WARN ] [MEMORY    ] Page fault: PID 14 page 5
[ 1667623 ms] [INFO ] [IO        ] PID 15 submitted Q6
[ 1667723 ms] [INFO ] [IO        ] PID 15 submitted Q7
[ 1667876 ms] [INFO ] [SCHEDULER ] PID 26 added to ready queue (remaining=95 ticks)
[ 1667876 ms] [INFO ] [SCHEDULER ] PID 27 added to ready queue (remaining=93 ticks)
[ 1667876 ms] [INFO ] [SCHEDULER ] PID 28 added to ready queue (remaining=92 ticks)
[ 1667876 ms] [INFO ] [SCHEDULER ] PID 29 added to ready queue (remaining=95 ticks)
[ 1667876 ms] [INFO ] [SCHEDULER ] PID 30 added to ready queue (remaining=100 ticks)
[ 1667923 ms] [INFO ] [IO        ] PID 15 submitted Q9
[ 1668623 ms] [INFO ] [IO        ] PID 15 submitted Q3
[ 1668824 ms] [INFO ] [IO        ] PID 15 submitted Q2
[ 1668824 ms] [INFO ] [IO        ] Flushed 5 submissions to disk
[ 1668924 ms] [INFO ] [IO        ] PID 15 submitted Q9
[ 1669224 ms] [INFO ] [IO        ] PID 15 submitted Q6
[ 1669278 ms] [INFO ] [SCHEDULER ] PID 15 terminated
[ 1669278 ms] [INFO ] [SCHEDULER ] PID 15 completed exam (PRIORITY)
[ 1669324 ms] [INFO ] [IO        ] PID 15 submitted Q6
[ 1669424 ms] [INFO ] [IO        ] PID 18 submitted Q8
[ 1669438 ms] [WARN ] [MEMORY    ] Page fault: PID 17 page 4
[ 1669538 ms] [WARN ] [MEMORY    ] Page fault: PID 17 page 0
[ 1669539 ms] [WARN ] [MEMORY    ] Page fault: PID 17 page 1
[ 1669624 ms] [INFO ] [IO        ] PID 18 submitted Q10
[ 1669639 ms] [WARN ] [MEMORY    ] Page fault: PID 17 page 5
[ 1669828 ms] [INFO ] [SCHEDULER ] PID 31 added to ready queue (remaining=100 ticks)
[ 1669828 ms] [INFO ] [SCHEDULER ] PID 32 added to ready queue (remaining=91 ticks)
[ 1669828 ms] [INFO ] [SCHEDULER ] PID 33 added to ready queue (remaining=92 ticks)
[ 1669828 ms] [INFO ] [SCHEDULER ] PID 34 added to ready queue (remaining=97 ticks)
[ 1669828 ms] [INFO ] [SCHEDULER ] PID 35 added to ready queue (remaining=99 ticks)
[ 1669840 ms] [WARN ] [MEMORY    ] Page fault: PID 17 page 2
[ 1669841 ms] [WARN ] [MEMORY    ] Page fault: PID 17 page 7
[ 1669841 ms] [WARN ] [MEMORY    ] Page fault: PID 17 page 6
